Workbook

Sheet table01
A1: id | B1: C03 | C1: C04 | D1: C06 | E1: C08 | F1: price | G1: img | I1: C09
A2: 0000000001 | B2: 0000000303 | C2: HLCC-108M Matte Photo Paper 108g A4 * 100 sheets | D2: пачка | E2: .230308 | F2: 1.9601534 | G2: url_1.png | H2: 1.9601534 | I2: =FIXED(H2,3) -> 1,960
A3: 0000000002 | B3: 0000000001 | C3: HLCC-115G Фотобумага глянцевая, 115 гр/см2, A4 * 100 листов | D3: пачка | E3: .230308 | F3: 2.3734686 | G3: url_2.png | H3: 2.3734686 | I3: =FIXED(H3,3) -> 2,373
A4: 0000000003 | B4: 0000000002 | C4: HLCC-140DG Фотобумага глянцевая двухсторонняя, 140 гр/см2, A4 * 20 листов | D4: пачка | E4: .230308 | F4: 0.71142191 | G4: url_3.png | H4: 0.71142191 | I4: =FIXED(H4,3) -> 0,711
A5: 0000000004 | B5: 0000000003 | C5: HLCC-180DG Фотобумага глянцевая двухсторонняя, 180 гр/см2, A4 *50 листов | D5: пачка | E5: .230308 | F5: 1.9948026 | G5: url_4.png | H5: 1.9948026 | I5: =FIXED(H5,3) -> 1,995
A6: 0000000005 | B6: 0000000004 | C6: HLCC-180G Фотобумага глянцевая, 180 гр/см2, 4R (10 на 15см) | D6: пачка | E6: .230308 | F6: 0.9008786 | G6: url_5.png | H6: 0.9008786 | I6: =FIXED(H6,3) -> 0,901
A7: 0000000006 | B7: 0000000005 | C7: HLCC-180G Фотобумага глянцевая, 180 гр/см2, A4 * 100 листов | D7: пачка | E7: .230510 | F7: 8.4753984 | G7: url_6.png | H7: 8.4753984 | I7: =FIXED(H7,3) -> 8,475
A8: 0000000007 | B8: 0000000302 | C8: HLCC-190М Фотобумага матовая, 190 гр/см2, 4R * 100 sheets | D8: пачка | E8: .230510 | F8: 1.8654256 | G8: url_7.png | H8: 1.8654256 | I8: =FIXED(H8,3) -> 1,865
A9: 0000000008 | B9: 0000000006 | C9: HLCC-190М Фотобумага матовая, 190 гр/см2, A4 * 100 листов | D9: пачка | E9: .230510 | F9: 6.8277926 | G9: url_8.png | H9: 6.8277926 | I9: =FIXED(H9,3) -> 6,828
A10: 0000000009 | B10: 0000000165 | C10: HLCC-200G Фотобумага глянцевая, 200 гр/см2, A4 * 100 листов | D10: пачка | E10: .230510 | F10: 6.4089096 | G10: url_9.png | H10: 6.4089096 | I10: =FIXED(H10,3) -> 6,409
A11: 0000000010 | B11: 0000000301 | C11: HLCC-210M Фотобумага матовая 210g A4 * 100 sheets | D11: пачка | E11: .230308 | F11: 3.1802995 | G11: url_10.png | H11: 3.1802995 | I11: =FIXED(H11,3) -> 3,180
A12: 0000000011 | B12: 0000000007 | C12: HLCC-230G Фотобумага глянцевая с обратной печатью, 230gsm, 5R (13 на 18) * 100 листов | D12: пачка | E12: .230308 | F12: 1.46904 | G12: url_11.png | H12: 1.46904 | I12: =FIXED(H12,3) -> 1,469
A13: 0000000012 | B13: 0000000008 | C13: HLCC-230G Фотобумага глянцевая, 230 гр/см2, 4R (10 на 15см) | D13: пачка | E13: .230308 | F13: 1.0394753 | G13: url_12.png | H13: 1.0394753 | I13: =FIXED(H13,3) -> 1,039
... A47: 0000000046 | B47: 0000000018 | C47: HTW-300EX Термотрансферная бумага для темных тканей (Голубая подложка), 300gsm, A4*20 листов | D47: пачка | E47: .230308 | F47: 14.228438 | G47: url_46.png | H47: 14.228438 | I47: =FIXED(H47,3) -> 14,228
A48: 0000000047 | B48: 0000000335 | C48: PCR (вал первичного заряда) Canon IR 2016/1600/2025 | D48: шт | E48: .230308 | F48: =598.66/85 -> 7.0430588 | G48: url_47.png | H48: 7.0430588 | I48: =FIXED(H48,3) -> 7,043
A49: 0000000048 | B49: 0000000197 | C49: PCR (вал первичного заряда) Samsung ML-1660/1860;SCX-3200 (D104) | D49: шт | E49: .210100 | F49: 1.2566667 | G49: url_48.png | H49: 1.2566667 | I49: =FIXED(H49,3) -> 1,257
A50: 0000000049 | B50: 0000000371 | C50: PCR (вал первичного заряда) для Pantum P2200/P2207/P2500W/M6600 (PC-211), Developer Roller, Тип 1.4 | D50: шт | E50: .230308 | F50: 1.51 | G50: url_49.png | H50: 1.51 | I50: =FIXED(H50,3) -> 1,510
A51: 0000000050 | B51: 0000000021 | C51: PCR (вал первичного заряда) для картриджей 12A Laser Jet HP 1010/1012/1015/3015/3020/3030 CANON 2900/3000 | D51: шт | E51: .230308 | F51: 0.50401163 | G51: url_50.png | H51: 0.50401163 | I51: =FIXED(H51,3) -> 0,504
A52: 0000000051 | B52: 0000000212 | C52: PCR (вал первичного заряда) для картриджей Canon PC/FC-128/230/330 | D52: шт | E52: .210516 | F52: 0.735 | G52: url_51.png | H52: 0.735 | I52: =FIXED(H52,3) -> 0,735
A53: 0000000052 | B53: 0000000022 | C53: PCR (вал первичного заряда) для картриджей P1005,388A,P1007,1008,1505,1522,278,285,435,436 | D53: шт | E53: .230308 | F53: 0.50401163 | G53: url_52.png | H53: 0.50401163 | I53: =FIXED(H53,3) -> 0,504
A54: 0000000053 | B54: 0000000185 | C54: PCR (вал первичного заряда) для картриджей Samsung ML-1610/2015 | D54: шт | E54: .210516 | F54: 0.735 | G54: url_53.png | H54: 0.735 | I54: =FIXED(H54,3) -> 0,735
A55: 0000000054 | B55: 0000000184 | C55: PCR (вал первичного заряда) для картриджей Samsung ML-1710/SCX-4200 | D55: шт | E55: .210516 | F55: 0.735 | G55: url_54.png | H55: 0.735 | I55: =FIXED(H55,3) -> 0,735
A56: 0000000055 | B56: 0000000211 | C56: PCR (вал первичного заряда) для картриджей Samsung ML-M2020/2070/2160/SCX-3400 | D56: шт | E56: .210516 | F56: 0.735 | G56: url_55.png | H56: 0.735 | I56: =FIXED(H56,3) -> 0,735
A57: 0000000056 | B57: 0000000331 | C57: PCR (вал первичного заряда) для принтеров M104/M102a/M130/M132/M106 (CF219A) | D57: шт | E57: .230308 | F57: =183.338/#REF! -> #REF! | G57: url_56.png | H57: 1.9928043 | I57: =FIXED(H57,3) -> 1,993
A58: 0000000057 | B58: 0000000023 | C58: T-образный держатель шлейфа для СНПЧ - клипса (система непрерывной подачи чернил), пластиковая планка для крепления шлейфа в СНПЧ | D58: шт | E58: .230308 | F58: 0.10956774 | G58: url_57.png | H58: 0.10956774 | I58: =FIXED(H58,3) -> 0,110
A59: 0000000058 | B59: 0000000271 | C59: USB Hub DE-V15 White | D59: шт | E59: .230308 | F59: 2.77 | G59: url_58.png | H59: 2.77 | I59: =FIXED(H59,3) -> 2,770
A60: 0000000059 | B60: 0000000258 | C60: Бушинг магнитного вала картриджа HP LJ 1010/1020 (Q2612A) (комплект 2шт) | D60: шт | E60: .230308 | F60: =5.39/#REF! -> #REF! | G60: url_59.png | H60: 0.058586957 | I60: =FIXED(H60,3) -> 0,059
A61: 0000000060 | B61: 0000000311 | C61: Бушинг резинового вала для HP LJ 1160/1320/3027 (Комплект) | D61: шт | E61: .230308 | F61: 1.4566667 | G61: url_60.png | H61: 1.4566667 | I61: =FIXED(H61,3) -> 1,457
A62: 0000000061 | B62: 0000000163 | C62: Бушинг резинового вала для HP LJ P1505/2035/M401/M425 | D62: шт | E62: .230308 | F62: 1.6562821 | G62: url_61.png | H62: 1.6562821 | I62: =FIXED(H62,3) -> 1,656
A63: 0000000062 | B63: 0000000029 | C63: Вал магнитный (magnetic roller) для картриджей HP Laser Jet 1000/1200/ | D63: шт | E63: .230308 | F63: =79.06/#REF! -> #REF! | G63: url_62.png | H63: 0.7906 | I63: =FIXED(H63,3) -> 0,791
A64: 0000000063 | B64: 0000000019 | C64: Вал магнитный (magnetic roller) для картриджей HP Laser Jet 1010/1012/1015/3015/3020/3030 CANON 2900/3000 | D64: шт | E64: .230308 | F64: 0.56975227 | G64: url_63.png | H64: 0.56975227 | I64: =FIXED(H64,3) -> 0,570
A65: 0000000064 | B65: 0000000287 | C65: Вал магнитный (magnetic roller) для картриджей HP Laser Jet 1100 | D65: шт | E65: .230308 | F65: =79.06/#REF! -> #REF! | G65: url_64.png | H65: 0.85934783 | I65: =FIXED(H65,3) -> 0,859
A66: 0000000065 | B66: 0000000221 | C66: Вал магнитный (magnetic roller) для картриджей HP Laser Jet 1320 | D66: шт | E66: .210516 | F66: 0 | G66: url_65.png | H66: 0 | I66: =FIXED(H66,3) -> 0,000
A67: 0000000066 | B67: 0000000222 | C67: Вал магнитный (magnetic roller) для картриджей HP Laser Jet 2035/2055 | D67: шт | E67: .210516 | F67: 0 | G67: url_66.png | H67: 0 | I67: =FIXED(H67,3) -> 0,000
A68: 0000000067 | B68: 0000000213 | C68: Вал магнитный (magnetic roller) для картриджей HP Laser Jet 2420 | D68: шт | E68: .210516 | F68: 2.7272727 | G68: url_67.png | H68: 2.7272727 | I68: =FIXED(H68,3) -> 2,727
A69: 0000000068 | B69: 0000000201 | C69: Вал магнитный (magnetic roller) для картриджей HP Laser Jet 4250 | D69: шт | E69: .210516 | F69: 2.7272727 | G69: url_68.png | H69: 2.7272727 | I69: =FIXED(H69,3) -> 2,727
A70: 0000000069 | B70: 0000000030 | C70: Вал магнитный (magnetic roller) для картриджей HP Laser Jet M104/M132, CF218A, CF217A, CF230A, CF234A, 047 | D70: шт | E70: .230308 | F70: 1.0513713 | G70: url_69.png | H70: 1.0513713 | I70: =FIXED(H70,3) -> 1,051
A71: 0000000070 | B71: 0000000281 | C71: Вал магнитный (magnetic roller) для картриджей HP Laser Jet M15/M28 CF244A | D71: шт | E71: .230308 | F71: 0.82 | G71: url_70.png | H71: 0.82 | I71: =FIXED(H71,3) -> 0,820
A72: 0000000071 | B72: 0000000020 | C72: Вал магнитный (magnetic roller) для картриджей HP Laser Jet P1005 1008 1505 1522 278 285 435 436 | D72: шт | E72: .230308 | F72: 0.56975227 | G72: url_71.png | H72: 0.56975227 | I72: =FIXED(H72,3) -> 0,570
A73: 0000000072 | B73: 0000000198 | C73: Вал магнитный Samsung ML-1660/1860;SCX-3200 (D104) | D73: шт | E73: .210516 | F73: 1.8366667 | G73: url_72.png | H73: 1.8366667 | I73: =FIXED(H73,3) -> 1,837
...

Sheet table01_01

Sheet table02
A1: =table02_01!Q2&table02_01!W1&table02_01!T2 -> 0000000001tel1_03
A2: =table02_01!Q3&table02_01!W2&table02_01!T3 -> 0000000002Лиля (Больница)
A3: =table02_01!Q4&table02_01!W3&table02_01!T4 -> 0000000003 Розница разное ОПТ
A4: =table02_01!Q5&table02_01!W4&table02_01!T5 -> 0000000004 Андрей (Ясиноватая)
A5: =table02_01!Q6&table02_01!W5&table02_01!T6 -> 0000000005 0713031515Юрий (Снежное)
A6: =table02_01!Q7&table02_01!W6&table02_01!T7 -> 0000000006 0713798238Артем Голубев+Тимофей+Игорь
A7: =table02_01!Q8&table02_01!W7&table02_01!T8 -> 0000000007 0713347913Наташа Алферова
A8: =table02_01!Q9&table02_01!W8&table02_01!T9 -> 0000000008 0713699176Оля Импульс
A9: =table02_01!Q10&table02_01!W9&table02_01!T10 -> 0000000009 0713853526Нистеренко Наташа
A10: =table02_01!Q11&table02_01!W10&table02_01!T11 -> 0000000010 0713306420Наташа Шахтерск
A11: =table02_01!Q12&table02_01!W11&table02_01!T12 -> 0000000011 0713260038Михаил Донпринт
A12: =table02_01!Q13&table02_01!W12&table02_01!T13 -> 0000000012 0713030110Богдан
... A90: =table02_01!Q91&table02_01!W90&table02_01!T91

Sheet table02_01
A1: id | B1: priz1 | C1: priz2 | D1: priz3 | E1: kod | F1: klient | G1: tel1 | H1: tel2 | I1: tel3 | J1: tel4 | L1: 180-" " | M1: kod_1 | N1: kod_2 | O1: kod_3 | P1: kod_4 | Q1: kod_5 | R1: klient_1 | S1: klient_2 | T1: klient_3 | U1: tel1_01 | V1: tel1_02 | W1: tel1_03
E2: 001 | F2: Розница | I2: 20210101 00 | K2: 0000000000 | L2: =REPT(" ",180) | M2: 001 | N2: =_xlfn.CONCAT(K2,M2) -> 0000000000001 | O2: =LEN(N2) -> 13 | P2: =RIGHT(N2,10) -> 0000000001 | Q2: 0000000001
E3: 002 | F3: Лиля (Больница) | I3: 20210101 01 | K3: 0000000000 | L3: =REPT(" ",180) | M3: 002 | N3: =_xlfn.CONCAT(K3,M3) -> 0000000000002 | O3: =LEN(N3) -> 13 | P3: =RIGHT(N3,10) -> 0000000002 | Q3: 0000000002 | R3: =_xlfn.CONCAT(F3,L3) -> Лиля (Больница) | S3: =LEFT(R3,180) -> Лиля (Больница) | T3: Лиля (Больница) | U3: =_xlfn.CONCAT(L3,G3) | V3: =RIGHT(U3,25)
E4: 003 | F4: Розница разное ОПТ | I4: 20210103 01 | K4: 0000000000 | L4: =REPT(" ",180) | M4: 003 | N4: =_xlfn.CONCAT(K4,M4) -> 0000000000003 | O4: =LEN(N4) -> 13 | P4: =RIGHT(N4,10) -> 0000000003 | Q4: 0000000003 | R4: =_xlfn.CONCAT(F4,L4) -> Розница разное ОПТ | S4: =LEFT(R4,180) -> Розница разное ОПТ | T4: Розница разное ОПТ | U4: =_xlfn.CONCAT(L4,G4) | V4: =RIGHT(U4,25)
E5: 004 | F5: Андрей (Ясиноватая) | G5: 0713031515 | I5: 20210103 02 | K5: 0000000000 | L5: =REPT(" ",180) | M5: 004 | N5: =_xlfn.CONCAT(K5,M5) -> 0000000000004 | O5: =LEN(N5) -> 13 | P5: =RIGHT(N5,10) -> 0000000004 | Q5: 0000000004 | R5: =_xlfn.CONCAT(F5,L5) -> Андрей (Ясиноватая) | S5: =LEFT(R5,180) -> Андрей (Ясиноватая) | T5: Андрей (Ясиноватая) | U5: =_xlfn.CONCAT(L5,G5) -> 0713031515 | V5: =RIGHT(U5,25) -> 0713031515 | W5: 0713031515
E6: 005 | F6: Юрий (Снежное) | G6: 0713798238 | I6: 20210129 01 | K6: 0000000000 | L6: =REPT(" ",180) | M6: 005 | N6: =_xlfn.CONCAT(K6,M6) -> 0000000000005 | O6: =LEN(N6) -> 13 | P6: =RIGHT(N6,10) -> 0000000005 | Q6: 0000000005 | R6: =_xlfn.CONCAT(F6,L6) -> Юрий (Снежное) | S6: =LEFT(R6,180) -> Юрий (Снежное) | T6: Юрий (Снежное) | U6: =_xlfn.CONCAT(L6,G6) -> 0713798238 | V6: =RIGHT(U6,25) -> 0713798238 | W6: 0713798238
E7: 006 | F7: Артем Голубев+Тимофей+Игорь | G7: 0713347913 | H7: 0951617232 | K7: 0000000000 | L7: =REPT(" ",180) | M7: 006 | N7: =_xlfn.CONCAT(K7,M7) -> 0000000000006 | O7: =LEN(N7) -> 13 | P7: =RIGHT(N7,10) -> 0000000006 | Q7: 0000000006 | R7: =_xlfn.CONCAT(F7,L7) -> Артем Голубев+Тимофей+Игорь | S7: =LEFT(R7,180) -> Артем Голубев+Тимофей+Игорь | T7: Артем Голубев+Тимофей+Игорь | U7: =_xlfn.CONCAT(L7,G7) -> 0713347913 | V7: =RIGHT(U7,25) -> 0713347913 | W7: 0713347913
E8: 007 | F8: Наташа Алферова | G8: 0713699176 | I8: 20210223 02 | K8: 0000000000 | L8: =REPT(" ",180) | M8: 007 | N8: =_xlfn.CONCAT(K8,M8) -> 0000000000007 | O8: =LEN(N8) -> 13 | P8: =RIGHT(N8,10) -> 0000000007 | Q8: 0000000007 | R8: =_xlfn.CONCAT(F8,L8) -> Наташа Алферова | S8: =LEFT(R8,180) -> Наташа Алферова | T8: Наташа Алферова | U8: =_xlfn.CONCAT(L8,G8) -> 0713699176 | V8: =RIGHT(U8,25) -> 0713699176 | W8: 0713699176
E9: 008 | F9: Оля Импульс | G9: 0713853526 | I9: 20210223 03 | J9: Саша | K9: 0000000000 | L9: =REPT(" ",180) | M9: 008 | N9: =_xlfn.CONCAT(K9,M9) -> 0000000000008 | O9: =LEN(N9) -> 13 | P9: =RIGHT(N9,10) -> 0000000008 | Q9: 0000000008 | R9: =_xlfn.CONCAT(F9,L9) -> Оля Импульс | S9: =LEFT(R9,180) -> Оля Импульс | T9: Оля Импульс | U9: =_xlfn.CONCAT(L9,G9) -> 0713853526 | V9: =RIGHT(U9,25) -> 0713853526 | W9: 0713853526
E10: 009 | F10: Нистеренко Наташа | G10: 0713306420 | H10: 0502426174 | I10: 20210223 04 | J10: Бумага | K10: 0000000000 | L10: =REPT(" ",180) | M10: 009 | N10: =_xlfn.CONCAT(K10,M10) -> 0000000000009 | O10: =LEN(N10) -> 13 | P10: =RIGHT(N10,10) -> 0000000009 | Q10: 0000000009 | R10: =_xlfn.CONCAT(F10,L10) -> Нистеренко Наташа | S10: =LEFT(R10,180) -> Нистеренко Наташа | T10: Нистеренко Наташа | U10: =_xlfn.CONCAT(L10,G10) -> 0713306420 | V10: =RIGHT(U10,25) -> 0713306420 | W10: 0713306420
E11: 010 | F11: Наташа Шахтерск | G11: 0713260038 | I11: 20210223 05 | J11: Бумага | K11: 0000000000 | L11: =REPT(" ",180) | M11: 010 | N11: =_xlfn.CONCAT(K11,M11) -> 0000000000010 | O11: =LEN(N11) -> 13 | P11: =RIGHT(N11,10) -> 0000000010 | Q11: 0000000010 | R11: =_xlfn.CONCAT(F11,L11) -> Наташа Шахтерск | S11: =LEFT(R11,180) -> Наташа Шахтерск | T11: Наташа Шахтерск | U11: =_xlfn.CONCAT(L11,G11) -> 0713260038 | V11: =RIGHT(U11,25) -> 0713260038 | W11: 0713260038
E12: 011 | F12: Михаил Донпринт | G12: 0713030110 | I12: 20210223 06 | J12: Рекламное агенство | K12: 0000000000 | L12: =REPT(" ",180) | M12: 011 | N12: =_xlfn.CONCAT(K12,M12) -> 0000000000011 | O12: =LEN(N12) -> 13 | P12: =RIGHT(N12,10) -> 0000000011 | Q12: 0000000011 | R12: =_xlfn.CONCAT(F12,L12) -> Михаил Донпринт | S12: =LEFT(R12,180) -> Михаил Донпринт | T12: Михаил Донпринт | U12: =_xlfn.CONCAT(L12,G12) -> 0713030110 | V12: =RIGHT(U12,25) -> 0713030110 | W12: 0713030110
E13: 012 | F13: Богдан | G13: 0713090610 | I13: 20210223 07 | K13: 0000000000 | L13: =REPT(" ",180) | M13: 012 | N13: =_xlfn.CONCAT(K13,M13) -> 0000000000012 | O13: =LEN(N13) -> 13 | P13: =RIGHT(N13,10) -> 0000000012 | Q13: 0000000012 | R13: =_xlfn.CONCAT(F13,L13) -> Богдан | S13: =LEFT(R13,180) -> Богдан | T13: Богдан | U13: =_xlfn.CONCAT(L13,G13) -> 0713090610 | V13: =RIGHT(U13,25) -> 0713090610 | W13: 0713090610
E14: 013 | F14: Брич Евгений | G14: 0713224491 | I14: 20210223 08 | K14: 0000000000 | L14: =REPT(" ",180) | M14: 013 | N14: =_xlfn.CONCAT(K14,M14) -> 0000000000013 | O14: =LEN(N14) -> 13 | P14: =RIGHT(N14,10) -> 0000000013 | Q14: 0000000013 | R14: =_xlfn.CONCAT(F14,L14) -> Брич Евгений | S14: =LEFT(R14,180) -> Брич Евгений | T14: Брич Евгений | U14: =_xlfn.CONCAT(L14,G14) -> 0713224491 | V14: =RIGHT(U14,25) -> 0713224491 | W14: 0713224491
E15: 014 | F15: Дед Мороз Александр Анатольевич | G15: 0713751323 | I15: 20210223 09 | K15: 0000000000 | L15: =REPT(" ",180) | M15: 014 | N15: =_xlfn.CONCAT(K15,M15) -> 0000000000014 | O15: =LEN(N15) -> 13 | P15: =RIGHT(N15,10) -> 0000000014 | Q15: 0000000014 | R15: =_xlfn.CONCAT(F15,L15) -> Дед Мороз Александр Анатольевич | S15: =LEFT(R15,180) -> Дед Мороз Александр Анатольевич | T15: Дед Мороз Александр Анатольевич | U15: =_xlfn.CONCAT(L15,G15) -> 0713751323 | V15: =RIGHT(U15,25) -> 0713751323 | W15: 0713751323
E16: 015 | F16: Гайваронская Наталья Владиславовна | G16: 0713215803 | I16: 20210223 10 | K16: 0000000000 | L16: =REPT(" ",180) | M16: 015 | N16: =_xlfn.CONCAT(K16,M16) -> 0000000000015 | O16: =LEN(N16) -> 13 | P16: =RIGHT(N16,10) -> 0000000015 | Q16: 0000000015 | R16: =_xlfn.CONCAT(F16,L16) -> Гайваронская Наталья Владиславовна | S16: =LEFT(R16,180) -> Гайваронская Наталья Владиславовна | T16: Гайваронская Наталья Владиславовна | U16: =_xlfn.CONCAT(L16,G16) -> 0713215803 | V16: =RIGHT(U16,25) -> 0713215803 | W16: 0713215803
E17: 016 | F17: Ира Гунько | G17: 0713330637 | I17: 20210223 11 | K17: 0000000000 | L17: =REPT(" ",180) | M17: 016 | N17: =_xlfn.CONCAT(K17,M17) -> 0000000000016 | O17: =LEN(N17) -> 13 | P17: =RIGHT(N17,10) -> 0000000016 | Q17: 0000000016 | R17: =_xlfn.CONCAT(F17,L17) -> Ира Гунько | S17: =LEFT(R17,180) -> Ира Гунько | T17: Ира Гунько | U17: =_xlfn.CONCAT(L17,G17) -> 0713330637 | V17: =RIGHT(U17,25) -> 0713330637 | W17: 0713330637
E18: 017 | F18: Быкадоров Данил Снежное | G18: 0713270040 | I18: 20210223 12 | K18: 0000000000 | L18: =REPT(" ",180) | M18: 017 | N18: =_xlfn.CONCAT(K18,M18) -> 0000000000017 | O18: =LEN(N18) -> 13 | P18: =RIGHT(N18,10) -> 0000000017 | Q18: 0000000017 | R18: =_xlfn.CONCAT(F18,L18) -> Быкадоров Данил Снежное | S18: =LEFT(R18,180) -> Быкадоров Данил Снежное | T18: Быкадоров Данил Снежное | U18: =_xlfn.CONCAT(L18,G18) -> 0713270040 | V18: =RIGHT(U18,25) -> 0713270040 | W18: 0713270040
E19: 018 | F19: Даша Золотое кольцо | G19: 0714765177 | I19: 20210223 13 | K19: 0000000000 | L19: =REPT(" ",180) | M19: 018 | N19: =_xlfn.CONCAT(K19,M19) -> 0000000000018 | O19: =LEN(N19) -> 13 | P19: =RIGHT(N19,10) -> 0000000018 | Q19: 0000000018 | R19: =_xlfn.CONCAT(F19,L19) -> Даша Золотое кольцо | S19: =LEFT(R19,180) -> Даша Золотое кольцо | T19: Даша Золотое кольцо | U19: =_xlfn.CONCAT(L19,G19) -> 0714765177 | V19: =RIGHT(U19,25) -> 0714765177 | W19: 0714765177
E20: 019 | F20: Александр Владимирович фотограф | G20: 0714663992 | I20: 20210223 14 | K20: 0000000000 | L20: =REPT(" ",180) | M20: 019 | N20: =_xlfn.CONCAT(K20,M20) -> 0000000000019 | O20: =LEN(N20) -> 13 | P20: =RIGHT(N20,10) -> 0000000019 | Q20: 0000000019 | R20: =_xlfn.CONCAT(F20,L20) -> Александр Владимирович фотограф | S20: =LEFT(R20,180) -> Александр Владимирович фотограф | T20: Александр Владимирович фотограф | U20: =_xlfn.CONCAT(L20,G20) -> 0714663992 | V20: =RIGHT(U20,25) -> 0714663992 | W20: 0714663992
E21: 020 | F21: Липучки Алена Макеевка | G21: 0714137173 | I21: 20210223 15 | K21: 0000000000 | L21: =REPT(" ",180) | M21: 020 | N21: =_xlfn.CONCAT(K21,M21) -> 0000000000020 | O21: =LEN(N21) -> 13 | P21: =RIGHT(N21,10) -> 0000000020 | Q21: 0000000020 | R21: =_xlfn.CONCAT(F21,L21) -> Липучки Алена Макеевка | S21: =LEFT(R21,180) -> Липучки Алена Макеевка | T21: Липучки Алена Макеевка | U21: =_xlfn.CONCAT(L21,G21) -> 0714137173 | V21: =RIGHT(U21,25) -> 0714137173 | W21: 0714137173
E22: 021 | F22: ФЛП Барановский Александр | I22: 20210307 01 | K22: 0000000000 | L22: =REPT(" ",180) | M22: 021 | N22: =_xlfn.CONCAT(K22,M22) -> 0000000000021 | O22: =LEN(N22) -> 13 | P22: =RIGHT(N22,10) -> 0000000021 | Q22: 0000000021 | R22: =_xlfn.CONCAT(F22,L22) -> ФЛП Барановский Александр | S22: =LEFT(R22,180) -> ФЛП Барановский Александр | T22: ФЛП Барановский Александр | U22: =_xlfn.CONCAT(L22,G22) | V22: =RIGHT(U22,25)
E23: 022 | F23: Ванин Сергей Алексеевич Докучаевск | G23: 0713137284 | I23: 20210307 02 | K23: 0000000000 | L23: =REPT(" ",180) | M23: 022 | N23: =_xlfn.CONCAT(K23,M23) -> 0000000000022 | O23: =LEN(N23) -> 13 | P23: =RIGHT(N23,10) -> 0000000022 | Q23: 0000000022 | R23: =_xlfn.CONCAT(F23,L23) -> Ванин Сергей Алексеевич Докучаевск | S23: =LEFT(R23,180) -> Ванин Сергей Алексеевич Докучаевск | T23: Ванин Сергей Алексеевич Докучаевск | U23: =_xlfn.CONCAT(L23,G23) -> 0713137284 | V23: =RIGHT(U23,25) -> 0713137284 | W23: 0713137284
E24: 023 | F24: НА ШАРУ - рынок | I24: 20210307 03 | K24: 0000000000 | L24: =REPT(" ",180) | M24: 023 | N24: =_xlfn.CONCAT(K24,M24) -> 0000000000023 | O24: =LEN(N24) -> 13 | P24: =RIGHT(N24,10) -> 0000000023 | Q24: 0000000023 | R24: =_xlfn.CONCAT(F24,L24) -> НА ШАРУ - рынок | S24: =LEFT(R24,180) -> НА ШАРУ - рынок | T24: НА ШАРУ - рынок | U24: =_xlfn.CONCAT(L24,G24) | V24: =RIGHT(U24,25)
E25: 024 | F25: Игорь Львович Юра | G25: 0713218918 | I25: 20210307 04 | K25: 0000000000 | L25: =REPT(" ",180) | M25: 024 | N25: =_xlfn.CONCAT(K25,M25) -> 0000000000024 | O25: =LEN(N25) -> 13 | P25: =RIGHT(N25,10) -> 0000000024 | Q25: 0000000024 | R25: =_xlfn.CONCAT(F25,L25) -> Игорь Львович Юра | S25: =LEFT(R25,180) -> Игорь Львович Юра | T25: Игорь Львович Юра | U25: =_xlfn.CONCAT(L25,G25) -> 0713218918 | V25: =RIGHT(U25,25) -> 0713218918 | W25: 0713218918
E26: 025 | F26: 196 Александр | G26: 0713148348 | I26: 20210307 05 | K26: 0000000000 | L26: =REPT(" ",180) | M26: 025 | N26: =_xlfn.CONCAT(K26,M26) -> 0000000000025 | O26: =LEN(N26) -> 13 | P26: =RIGHT(N26,10) -> 0000000025 | Q26: 0000000025 | R26: =_xlfn.CONCAT(F26,L26) -> 196 Александр | S26: =LEFT(R26,180) -> 196 Александр | T26: 196 Александр | U26: =_xlfn.CONCAT(L26,G26) -> 0713148348 | V26: =RIGHT(U26,25) -> 0713148348 | W26: 0713148348
E27: 026 | F27: Борис Викторович Енакиево Электроника | I27: 20210307 06 | K27: 0000000000 | L27: =REPT(" ",180) | M27: 026 | N27: =_xlfn.CONCAT(K27,M27) -> 0000000000026 | O27: =LEN(N27) -> 13 | P27: =RIGHT(N27,10) -> 0000000026 | Q27: 0000000026 | R27: =_xlfn.CONCAT(F27,L27) -> Борис Викторович Енакиево Электроника | S27: =LEFT(R27,180) -> Борис Викторович Енакиево Электроника | T27: Борис Викторович Енакиево Электроника | U27: =_xlfn.CONCAT(L27,G27) | V27: =RIGHT(U27,25)
E28: 027 | F28: Сидоренко Петровка Донецк | G28: 0713315352 | I28: 20210307 07 | K28: 0000000000 | L28: =REPT(" ",180) | M28: 027 | N28: =_xlfn.CONCAT(K28,M28) -> 0000000000027 | O28: =LEN(N28) -> 13 | P28: =RIGHT(N28,10) -> 0000000027 | Q28: 0000000027 | R28: =_xlfn.CONCAT(F28,L28) -> Сидоренко Петровка Донецк | S28: =LEFT(R28,180) -> Сидоренко Петровка Донецк | T28: Сидоренко Петровка Донецк | U28: =_xlfn.CONCAT(L28,G28) -> 0713315352 | V28: =RIGHT(U28,25) -> 0713315352 | W28: 0713315352
E29: 028 | F29: ФЛП Чуприн Юра | G29: 0713360190 | I29: 20210307 08 | K29: 0000000000 | L29: =REPT(" ",180) | M29: 028 | N29: =_xlfn.CONCAT(K29,M29) -> 0000000000028 | O29: =LEN(N29) -> 13 | P29: =RIGHT(N29,10) -> 0000000028 | Q29: 0000000028 | R29: =_xlfn.CONCAT(F29,L29) -> ФЛП Чуприн Юра | S29: =LEFT(R29,180) -> ФЛП Чуприн Юра | T29: ФЛП Чуприн Юра | U29: =_xlfn.CONCAT(L29,G29) -> 0713360190 | V29: =RIGHT(U29,25) -> 0713360190 | W29: 0713360190
E30: 029 | F30: Администрация | I30: 20210307 09 | K30: 0000000000 | L30: =REPT(" ",180) | M30: 029 | N30: =_xlfn.CONCAT(K30,M30) -> 0000000000029 | O30: =LEN(N30) -> 13 | P30: =RIGHT(N30,10) -> 0000000029 | Q30: 0000000029 | R30: =_xlfn.CONCAT(F30,L30) -> Администрация | S30: =LEFT(R30,180) -> Администрация | T30: Администрация | U30: =_xlfn.CONCAT(L30,G30) | V30: =RIGHT(U30,25)
E31: 030 | F31: Людмила Степановна | G31: 0713114488 | I31: 20210307 10 | K31: 0000000000 | L31: =REPT(" ",180) | M31: 030 | N31: =_xlfn.CONCAT(K31,M31) -> 0000000000030 | O31: =LEN(N31) -> 13 | P31: =RIGHT(N31,10) -> 0000000030 | Q31: 0000000030 | R31: =_xlfn.CONCAT(F31,L31) -> Людмила Степановна | S31: =LEFT(R31,180) -> Людмила Степановна | T31: Людмила Степановна | U31: =_xlfn.CONCAT(L31,G31) -> 0713114488 | V31: =RIGHT(U31,25) -> 0713114488 | W31: 0713114488
E32: 031 | F32: Руслан Снежное | I32: 20210307 11 | K32: 0000000000 | L32: =REPT(" ",180) | M32: 031 | N32: =_xlfn.CONCAT(K32,M32) -> 0000000000031 | O32: =LEN(N32) -> 13 | P32: =RIGHT(N32,10) -> 0000000031 | Q32: 0000000031 | R32: =_xlfn.CONCAT(F32,L32) -> Руслан Снежное | S32: =LEFT(R32,180) -> Руслан Снежное | T32: Руслан Снежное | U32: =_xlfn.CONCAT(L32,G32) | V32: =RIGHT(U32,25)
E33: 032 | F33: Игорь АБС ABC | G33: 0713407565 | I33: 20210307 12 | K33: 0000000000 | L33: =REPT(" ",180) | M33: 032 | N33: =_xlfn.CONCAT(K33,M33) -> 0000000000032 | O33: =LEN(N33) -> 13 | P33: =RIGHT(N33,10) -> 0000000032 | Q33: 0000000032 | R33: =_xlfn.CONCAT(F33,L33) -> Игорь АБС ABC | S33: =LEFT(R33,180) -> Игорь АБС ABC | T33: Игорь АБС ABC | U33: =_xlfn.CONCAT(L33,G33) -> 0713407565 | V33: =RIGHT(U33,25) -> 0713407565 | W33: 0713407565
E34: 033 | F34: Варлянский Валерий | G34: 0713664072 | I34: 20210307 13 | K34: 0000000000 | L34: =REPT(" ",180) | M34: 033 | N34: =_xlfn.CONCAT(K34,M34) -> 0000000000033 | O34: =LEN(N34) -> 13 | P34: =RIGHT(N34,10) -> 0000000033 | Q34: 0000000033 | R34: =_xlfn.CONCAT(F34,L34) -> Варлянский Валерий | S34: =LEFT(R34,180) -> Варлянский Валерий | T34: Варлянский Валерий | U34: =_xlfn.CONCAT(L34,G34) -> 0713664072 | V34: =RIGHT(U34,25) -> 0713664072 | W34: 0713664072
E35: 034 | F35: ФЛП Кислякова-Осипенко | G35: 0713397760 | I35: 20210307 14 | K35: 0000000000 | L35: =REPT(" ",180) | M35: 034 | N35: =_xlfn.CONCAT(K35,M35) -> 0000000000034 | O35: =LEN(N35) -> 13 | P35: =RIGHT(N35,10) -> 0000000034 | Q35: 0000000034 | R35: =_xlfn.CONCAT(F35,L35) -> ФЛП Кислякова-Осипенко | S35: =LEFT(R35,180) -> ФЛП Кислякова-Осипенко | T35: ФЛП Кислякова-Осипенко | U35: =_xlfn.CONCAT(L35,G35) -> 0713397760 | V35: =RIGHT(U35,25) -> 0713397760 | W35: 0713397760
E36: 035 | F36: Юля Тан | G36: 071 | I36: 20210307 15 | K36: 0000000000 | L36: =REPT(" ",180) | M36: 035 | N36: =_xlfn.CONCAT(K36,M36) -> 0000000000035 | O36: =LEN(N36) -> 13 | P36: =RIGHT(N36,10) -> 0000000035 | Q36: 0000000035 | R36: =_xlfn.CONCAT(F36,L36) -> Юля Тан | S36: =LEFT(R36,180) -> Юля Тан | T36: Юля Тан | U36: =_xlfn.CONCAT(L36,G36) -> 071 | V36: =RIGHT(U36,25) -> 071 | W36: 071
E37: 036 | F37: ФЛП Черевайко Андрей Николаевич | G37: 0713190950 | I37: 20210307 16 | K37: 0000000000 | L37: =REPT(" ",180) | M37: 036 | N37: =_xlfn.CONCAT(K37,M37) -> 0000000000036 | O37: =LEN(N37) -> 13 | P37: =RIGHT(N37,10) -> 0000000036 | Q37: 0000000036 | R37: =_xlfn.CONCAT(F37,L37) -> ФЛП Черевайко Андрей Николаевич | S37: =LEFT(R37,180) -> ФЛП Черевайко Андрей Николаевич | T37: ФЛП Черевайко Андрей Николаевич | U37: =_xlfn.CONCAT(L37,G37) -> 0713190950 | V37: =RIGHT(U37,25) -> 0713190950 | W37: 0713190950
E38: 037 | F38: Еременко Дима | G38: 0714671087 | I38: 20210307 17 | K38: 0000000000 | L38: =REPT(" ",180) | M38: 037 | N38: =_xlfn.CONCAT(K38,M38) -> 0000000000037 | O38: =LEN(N38) -> 13 | P38: =RIGHT(N38,10) -> 0000000037 | Q38: 0000000037 | R38: =_xlfn.CONCAT(F38,L38) -> Еременко Дима | S38: =LEFT(R38,180) -> Еременко Дима | T38: Еременко Дима | U38: =_xlfn.CONCAT(L38,G38) -> 0714671087 | V38: =RIGHT(U38,25) -> 0714671087 | W38: 0714671087
E39: 038 | F39: ФЛП Барбатун Вадим Олегович | G39: 0714751449 | I39: 20210307 18 | K39: 0000000000 | L39: =REPT(" ",180) | M39: 038 | N39: =_xlfn.CONCAT(K39,M39) -> 0000000000038 | O39: =LEN(N39) -> 13 | P39: =RIGHT(N39,10) -> 0000000038 | Q39: 0000000038 | R39: =_xlfn.CONCAT(F39,L39) -> ФЛП Барбатун Вадим Олегович | S39: =LEFT(R39,180) -> ФЛП Барбатун Вадим Олегович | T39: ФЛП Барбатун Вадим Олегович | U39: =_xlfn.CONCAT(L39,G39) -> 0714751449 | V39: =RIGHT(U39,25) -> 0714751449 | W39: 0714751449
E40: 039 | F40: Женя Полиграф | I40: 20210307 19 | K40: 0000000000 | L40: =REPT(" ",180) | M40: 039 | N40: =_xlfn.CONCAT(K40,M40) -> 0000000000039 | O40: =LEN(N40) -> 13 | P40: =RIGHT(N40,10) -> 0000000039 | Q40: 0000000039 | R40: =_xlfn.CONCAT(F40,L40) -> Женя Полиграф | S40: =LEFT(R40,180) -> Женя Полиграф | T40: Женя Полиграф | U40: =_xlfn.CONCAT(L40,G40) | V40: =RIGHT(U40,25)
...

Sheet table03
A1: a1 | B1: a1 | C1: a2 | D1: a3 | E1: a4 | F1: a5 | G1: a6 | H1: a7 | I1: a8 | J1: a9 | K1: a10 | L1: a11 | M1: a12 | N1: a13 | O1: a14 | P1: a15
C2: Розница | D2: НАКЛАДНАЯ N | F2: 4110 | J2: Розн | K2: Опт | L2: Опт | M2: Клиент | N2: Курс | O2: 4110 | P2: 45412.623
F3: 45412.623 | J3: Цена | K3: 0 | M3: 1 | N3: 110 | O3: 4110 | P3: 45412.623
C4: Наименование товара | D4: Ед | E4: Кол-во | F4: Цена | G4: Сумма | H4: Остаток | I4: Код | J4: 0 | K4: 1 | L4: 2 | O4: 4110 | P4: 45412.623
B5: 1 | C5: Заправка лазерного картриджа | D5: шт | E5: 4 | F5: 350 | G5: 1400 | H5: -4 | I5: 167 | J5: 462 | K5: 370 | L5: 323 | M5: 1 | N5: 110 | O5: 4110 | P5: 45412.623
B6: 2 | C6: Заправка лазерного картриджа | D6: шт | E6: 7 | F6: 400 | G6: 2800 | H6: -7 | I6: 167 | J6: 462 | K6: 370 | L6: 323 | M6: 1 | N6: 110 | O6: 4110 | P6: 45412.623
B7: 3 | C7: Чернила Canon 100мл Black | D7: шт | E7: 3 | F7: 300 | G7: 900 | H7: -3 | I7: 117 | J7: 180 | K7: 144 | L7: 126 | M7: 1 | N7: 110 | O7: 4110 | P7: 45412.623
B8: 4 | C8: Фотобумага Hi-Image Paper глянцевая односторонняя, A4, 230 г/м2, 100 л. | D8: шт | E8: 1 | F8: 1100 | G8: 1100 | H8: -1 | I8: 389 | J8: 1291 | K8: 1205 | L8: 1119 | M8: 1 | N8: 110 | O8: 4110 | P8: 45412.623
B9: 5 | C9: Картридж лазерный HP LJ 285A/Canon 725 | D9: шт | E9: 1 | F9: 800 | G9: 800 | H9: 4 | I9: 175 | J9: 874 | K9: 728 | L9: 680 | M9: 1 | N9: 110 | O9: 4110 | P9: 45412.623
E10: Всего | F10: 7000 | O10: 4110 | P10: 45412.623
C11: Розница | D11: НАКЛАДНАЯ N | F11: 4109 | J11: Розн | K11: Опт | L11: Опт | M11: Клиент | N11: Курс | O11: 4109 | P11: 45410.623
F12: 45410.623 | J12: Цена | K12: 0 | M12: 1 | N12: 110 | O12: 4109 | P12: 45410.623
C13: Наименование товара | D13: Ед | E13: Кол-во | F13: Цена | G13: Сумма | H13: Остаток | I13: Код | J13: 0 | K13: 1 | L13: 2 | O13: 4109 | P13: 45410.623
B14: 1 | C14: Тонер Samsung ML-1210/1710/SCX-4200 (500г) | D14: шт | E14: 1 | F14: 800 | G14: 800 | H14: -1 | I14: 99 | J14: 755 | K14: 705 | L14: 655 | M14: 1 | N14: 110 | O14: 4109 | P14: 45410.623
B15: 2 | C15: Чернила Epson T50 100мл Black | D15: шт | E15: 1 | F15: 250 | G15: 250 | H15: -1 | I15: 127 | J15: 180 | K15: 144 | L15: 126 | M15: 1 | N15: 110 | O15: 4109 | P15: 45410.623
B16: 3 | C16: Заправка лазерного картриджа | D16: шт | E16: 4 | F16: 400 | G16: 1600 | H16: -4 | I16: 167 | J16: 462 | K16: 370 | L16: 323 | M16: 1 | N16: 110 | O16: 4109 | P16: 45410.623
B17: 4 | C17: Ремонт струйного принтера | D17: шт | E17: 1 | F17: 1500 | G17: 1500 | H17: -1 | I17: 170 | J17: 462 | K17: 370 | L17: 323 | M17: 1 | N17: 110 | O17: 4109 | P17: 45410.623
B18: 5 | C18: Ремонт лазерного принтера | D18: шт | E18: 1 | F18: 400 | G18: 400 | H18: -1 | I18: 169 | J18: 462 | K18: 370 | L18: 323 | M18: 1 | N18: 110 | O18: 4109 | P18: 45410.623
B19: 6 | C19: Тонер Samsung ML-1210/1710/SCX-4200 ( 90г) | D19: шт | E19: 1 | F19: 200 | G19: 200 | H19: -1 | I19: 98 | J19: 151 | K19: 141 | L19: 131 | M19: 1 | N19: 110 | O19: 4109 | P19: 45410.623
E20: Всего | F20: 4750 | O20: 4109 | P20: 45410.623
C21: Розница | D21: НАКЛАДНАЯ N | F21: 4108 | J21: Розн | K21: Опт | L21: Опт | M21: Клиент | N21: Курс | O21: 4108 | P21: 45409.459
F22: 45409.459 | J22: Цена | K22: 0 | M22: 1 | N22: 110 | O22: 4108 | P22: 45409.459
C23: Наименование товара | D23: Ед | E23: Кол-во | F23: Цена | G23: Сумма | H23: Остаток | I23: Код | J23: 0 | K23: 1 | L23: 2 | O23: 4108 | P23: 45409.459
B24: 1 | C24: Картридж лазерный HP LJ 2612A/C103/303/703/FX9/10/L90/C104 | D24: шт | E24: 1 | F24: 900 | G24: 900 | H24: 15 | I24: 33 | J24: 876 | K24: 730 | L24: 681 | M24: 1 | N24: 110 | O24: 4108 | P24: 45409.459
B25: 2 | C25: Заправка лазерного картриджа | D25: шт | E25: 2 | F25: 350 | G25: 700 | H25: -2 | I25: 167 | J25: 462 | K25: 370 | L25: 323 | M25: 1 | N25: 110 | O25: 4108 | P25: 45409.459
B26: 3 | C26: Заправка лазерного картриджа | D26: шт | E26: 2 | F26: 400 | G26: 800 | H26: -2 | I26: 167 | J26: 462 | K26: 370 | L26: 323 | M26: 1 | N26: 110 | O26: 4108 | P26: 45409.459
B27: 4 | C27: Чернила Epson T50 100мл Black | D27: шт | E27: 2 | F27: 250 | G27: 500 | H27: -2 | I27: 127 | J27: 180 | K27: 144 | L27: 126 | M27: 1 | N27: 110 | O27: 4108 | P27: 45409.459
B28: 5 | C28: Фотобумага Hi-Image Paper матовая односторонняя, A4, 230 г/м2, 100 л. | D28: шт | E28: 1 | F28: 800 | G28: 800 | H28: -1 | I28: 391 | J28: 908 | K28: 847 | L28: 787 | M28: 1 | N28: 110 | O28: 4108 | P28: 45409.459
B29: 6 | C29: Заправка лазерного картриджа | D29: шт | E29: 4 | F29: 400 | G29: 1600 | H29: -4 | I29: 167 | J29: 462 | K29: 370 | L29: 323 | M29: 1 | N29: 110 | O29: 4108 | P29: 45409.459
B30: 7 | C30: HLCC-180G Фотобумага глянцевая, 180 гр/см2, 4R (10 на 15см) | D30: пачка | E30: 1 | F30: 250 | G30: 250 | H30: -1 | I30: 4 | J30: 248 | K30: 198 | L30: 188 | M30: 1 | N30: 110 | O30: 4108 | P30: 45409.459
B31: 8 | C31: Кабель питания 1.2м | D31: шт | E31: 1 | F31: 150 | G31: 150 | H31: -1 | I31: 274 | J31: 107 | K31: 95 | L31: 95 | M31: 1 | N31: 110 | O31: 4108 | P31: 45409.459
E32: Всего | F32: 5700 | O32: 4108 | P32: 45409.459
C33: Женя Полиграф | D33: НАКЛАДНАЯ N | F33: 4107 | J33: Розн | K33: Опт | L33: Опт | M33: Клиент | N33: Курс | O33: 4107 | P33: 45408.674
F34: 45408.674 | J34: Цена | K34: 0 | M34: 39 | N34: 110 | O34: 4107 | P34: 45408.674
C35: Наименование товара | D35: Ед | E35: Кол-во | F35: Цена | G35: Сумма | H35: Остаток | I35: Код | J35: 0 | K35: 1 | L35: 2 | O35: 4107 | P35: 45408.674
B36: 1 | C36: Фотобумага NetProduct глянцевая односторонняя, 10x15 см, 230 г/м2, 500 л. | D36: шт | E36: 1 | F36: 1300 | G36: 1300 | H36: 0 | I36: 390 | J36: 1648 | K36: 1538 | L36: 1428 | M36: 39 | N36: 110 | O36: 4107 | P36: 45408.674
B37: 2 | C37: Фотобумага Hi-Image Paper глянцевая односторонняя, A4, 230 г/м2, 100 л. | D37: шт | E37: 1 | F37: 1000 | G37: 1000 | H37: -1 | I37: 389 | J37: 1291 | K37: 1205 | L37: 1119 | M37: 39 | N37: 110 | O37: 4107 | P37: 45408.674
E38: Всего | F38: 2300 | O38: 4107 | P38: 45408.674
C39: Розница | D39: НАКЛАДНАЯ N | F39: 4106 | J39: Розн | K39: Опт | L39: Опт | M39: Клиент | N39: Курс | O39: 4106 | P39: 45408.674
F40: 45408.674 | J40: Цена | K40: 0 | M40: 1 | N40: 110 | O40: 4106 | P40: 45408.674
...

Sheet table03_01
